Workbook

Sheet Inputs
A1: Key | B1: Description | C1: Value | D1: Unit / Notes
A2: Devices | B2: Количество устройств (NAC endpoints) | C2: 8000 | D2: шт
A3: Access Method | B3: Механизм аутентификации | C3: MAB
A4: PeakRpsInput | B4: Пиковый RPS (если задан напрямую) | C4: 0 | D4: req/s
A5: HeadroomPct | B5: Запас по производительности (Headroom H), % | C5: 25 | D5: %
A6: DcCount | B6: Количество ЦОД (active-active) | C6: 1 | D6: шт
A7: GatewayEnabled | B7: Учитывать накладные Gateway (0 = нет, 1 = да) | C7: 1 | D7: 0/1
A8: GatewayOverheadPct | B8: Надбавка Gateway, % | C8: 10 | D8: %
A9: OcspEnabled | B9: Учитывать OCSP (0 = нет, 1 = да) | C9: 1 | D9: 0/1
A10: AccountingEnabled | B10: Учитывать аудит (аккаунтинг) | C10: 1 | D10: 0/1
A11: MacSpoofing | B11: Учитывать МАС-spoofing (только для МАВ) (0 = нет, 1 = да) | C11: 1 | D11: 0/1
A12: NodeCountPerDc | B12: Количество нод в одном ЦОД | C12: 3 | D12: шт
A13: AuthAttemptsPerDevicePerDay | B13: Количество подключений каждого устройства в день | C13: 2 | D13: раз(а)
A14: Retention_days | B14: Период сохранения данных в БД, дней | C14: 14 | D14: дней
A15: СПРАВОЧНЫЕ ДАННЫЕ, НЕ МЕНЯТЬ:
A16: ConcurrentPeakPct | B16: Одновременные подключения, % | C16: 30 | D16: %
A17: BurstWindowSec | B17: Окно всплеска, сек | C17: 60 | D17: сек
A18: SLA_p95_sec | B18: Целевой p95, сек | C18: 1.5 | D18: сек

Sheet Coefficients
A1: Mechanism | B1: Коэфф | C1: Значение | D1: Описание | E1: Методика рассчета
A2: EAP-TLS | B2: NominalRpsPerPod | C2: 20 | D2: Комфортный RPS на один pod (без OCSP) | E2: Комфортный RPS на один pod (без OCSP). Выбран на основе тестов 45 и 126: pod выдерживает 20–26 RPS, для модели берём консервативное значение 20 RPS/pod.
A3: EAP-TLS | B3: CpuPeakPerRps | C3: 0.09 | D3: Пиковое потребление CPU (core) на 1 RPS/pod | E3: Коэффициент получен из измерений нагрузки: pod edo-radius потреблял ~2.0–2.3 core при нагрузке ~22–25 RPS. Пример оценки: 2.1 core / 23 RPS ≈ 0.091 core на 1 RPS на pod. Для модели округляем до 0.09 core/RPS/pod.
A4: EAP-TLS | B4: MemPeakPerRpsMiB | C4: 40 | D4: Пиковое потребление памяти (MiB) на 1 RPS/pod | E4: По замерам pod потреблял ~0.8–1.1 GiB памяти при ~22–25 RPS. Оценка: около 1000 MiB / 25 RPS ≈ 40 MiB на 1 RPS. Для модели принимаем 40 MiB/RPS/pod.
A5: EAP-TLS | B5: OCSP_Include, % | C5: 14
A6: Общее | B6: SafetyFactor | C6: 1.25 | D6: Запас между peak и limit по ресурсам pod | E6: Лимиты ресурсов пода выставляем выше измеренного пика. Коэффициент 1.25 даёт +25% запаса по CPU и памяти относительно наблюдённого максимума. Это уменьшает риск throttling’а и даёт пространство для флуктуаций нагрузки.
A7: Общее | B7: MaxNodeUtilization | C7: 0.7 | D7: Максимальная целевая загрузка ноды (70%) | E7: Инженерная практика, чтобы держать хороший баланс между эффективностью и запасом по ресурсу, не выводилась из измерений напрямую.
A8: Общее | B8: NodeHeadroom | C8: 1.15
A9: МАВ | B9: Baseline_NodeCPU_p95 | C9: 4
A10: PEAP | B10: Baseline_NodeCPU_p95 | C10: 4
A11: EAP-TLS | B11: Baseline_NodeCPU_p95 | C11: 5.1
A12: TEAP | B12: Baseline_NodeCPU_p95 | C12: 5
A13: Общее | B13: Baseline_NodeMemGiB_p95 | C13: =10+Inputs!C2*0.0006 -> 14.8 | D13: Базовая загрузка по памяти
A14: MAB | B14: NominalRpsPerPod | C14: 27 | D14: Комфортный RPS на один pod
A15: MAB | B15: CpuPeakPerRps | C15: 0.08871 | D15: Пиковое потребление CPU (core) на 1 RPS/pod
A16: MAB | B16: MemPeakPerRpsMiB | C16: 32.44 | D16: Пиковое потребление памяти (MiB) на 1 RPS/pod
A17: PEAP | B17: NominalRpsPerPod | C17: 12 | D17: Комфортный RPS на один pod | E17: По отфильтрованным прогонам PEAP (без таймаутов и с Iteration Duration Max < 40s): медиана Client Peak RPS/pod ≈ 11.6, p75 ≈ 12.9; для модели берём консервативно 12 RPS/pod.
A18: PEAP | B18: CpuPeakPerRps | C18: 0.21 | D18: Пиковое потребление CPU (core) на 1 RPS на pod | E18: Оценка по пикам CPU и фактическому RPS/pod в выбранных прогонах. При RPS/pod ~10–15 наблюдаем 0.19–0.23 core/RPS; берём 0.21 core/RPS/pod.
A19: PEAP | B19: MemPeakPerRpsMiB | C19: 70 | D19: Пиковое потребление памяти (MiB) на 1 RPS на pod | E19: Для RPS/pod ~10–15 наблюдаем ~60–84 MiB/RPS (медиана ~70); для модели берём 70 MiB/RPS/pod.
A20: EAP-TEAP | B20: NominalRpsPerPod | C20: 7.4 | D20: Комфортный RPS на один pod
A21: EAP-TEAP | B21: CpuPeakPerRps | C21: 0.23 | D21: Пиковое потребление CPU (core) на 1 RPS/pod
A22: EAP-TEAP | B22: MemPeakPerRpsMiB | C22: 85 | D22: Пиковое потребление памяти (MiB) на 1 RPS/pod
A23: MAB_MAC_Spoofing | B23: NominalRpsPerPod | C23: 20 | D23: Sweet spot по latency (18–22 RPS/pod)
A24: MAB_MAC_Spoofing | B24: CpuPeakPerRps | C24: 0.14 | D24: Envelope по всем прогонам c включенным спуфингом
A25: MAB_MAC_Spoofing | B25: MemPeakPerRpsMiB | C25: 50 | D25: Учитывает accounting + state
A26: MAB+Accounting | B26: NominalRpsPerPod | C26: 22 | D26: Комфортный RPS на pod с accounting
A27: MAB+Accounting | B27: CpuPeakPerRps | C27: 0.11 | D27: CPU peak per RPS/pod (≈ +23%)
A28: MAB+Accounting | B28: MemPeakPerRpsMiB | C28: 40 | D28: Memory peak per RPS/pod (≈ +23%)
A29: Общее+Accounting | B29: AccountingCpuOverhead | C29: 1.23
A30: Общее+Accounting | B30: AccountingMemOverhead | C30: 1.23
A31: MAB_MAC_Spoofing | B31: SpoofingMemOverhead | C31: =(C25-C28)/C28+1 -> 1.25 | D31: Дополнительный оверхед памяти с проверкой на МАС-спуфинг (по сравнению с МАВ + аккаунтинг)
A32: MAB_MAC_Spoofing | B32: SpoofingCpuOverhead | C32: =(C24-C27)/C27+1 -> 1.2727273 | D32: Дополнительный оверхед по процу с проверкой на МАС-спуфинг (по сравнению с МАВ+аккаунтинг)
B33: AccountingOverheadPeakRps | C33: =C26/C14 -> 0.81481481
A34: Общее | B34: BytesPerAccountingSession | C34: 519 | D34: Средний объём одной accounting-сессии в acs.radacct | E34: Общий размер таблицы radacct (heap + indexes) / общее число строк. Подтверждено замерами на MAB-прогонах.
A35: MAB | B35: BytesPerAuthAttempt | C35: 9248 | D35: Средний объём данных на одну попытку аутентификации MAB (без учёта accounting) | E35: acs.radpostauth (1 748 B/auth) + acs.trace_rad_auth_messages (≈7 500 B/auth).
A36: MAB (no spoofing) | B36: BytesPerSession | C36: 9767 | D36: Средний объём данных на одну MAB-сессию без MAC-spoofing | E36: BytesPerAccountingSession + BytesPerAuthAttempt.
A37: MAB (with spoofing) | B37: BytesPerSessionSpoofing | C37: 19016 | D37: Средний объём данных на одну MAB-сессию с MAC-spoofing | E37: BytesPerAccountingSession + 2 × BytesPerAuthAttempt (два auth attempt на одну сессию).
A38: PEAP MSCHAPv2 | B38: BytesPerAuthAttempt | C38: 44882 | D38: Средний объём данных на одну аутентификацию PEAP | E38: acs.radpostauth (≈4.2 KB/auth) + acs.trace_rad_auth_messages (≈39.7 KB/auth), рассчитано по окну теста.
A39: EAP-TLS | B39: BytesPerAuthAttempt | C39: 36016 | D39: Средний объём данных на одну аутентификацию EAP-TLS | E39: acs.radpostauth (≈4.1 KB/auth) + acs.trace_rad_auth_messages (≈22.6 KB/auth), по нагрузочным замерам.
A40: TEAP | B40: BytesPerAuthAttempt | C40: 168447 | D40: Средний объём данных на одну аутентификацию TEAP | E40: acs.radpostauth (≈3.4 KB/auth) + acs.trace_rad_auth_messages (≈161 KB/auth). Высокий объём обусловлен количеством trace-событий (~268 на auth).
...

Sheet Вычисления
A1: Parameter | B1: Description | C1: EAP-TLS | D1: MAB | E1: PEAP | F1: MAB + Acct + MAC-spoofing | G1: MAB + Acct | H1: PEAP + Acct | I1: TEAP + Acct
A2: Devices | B2: Количество устройств | C2: =Inputs!$C2 -> 8000 | D2: =Inputs!$C2 -> 8000 | E2: =Inputs!$C2 -> 8000 | F2: =Inputs!$C2 -> 8000 | G2: =Inputs!$C2 -> 8000 | H2: =Inputs!$C2 -> 8000 | I2: =Inputs!$C2 -> 8000
A3: ConcurrentPeakPct | B3: Одновременные подключения, % | C3: =Inputs!C16 -> 30 | D3: =Inputs!C16 -> 30 | E3: =Inputs!C16 -> 30 | F3: =Inputs!$C16 -> 30 | G3: =Inputs!$C16 -> 30 | H3: =Inputs!$C16 -> 30 | I3: =Inputs!$C16 -> 30
A4: BurstWindowSec | B4: Окно всплеска, сек | C4: =Inputs!C17 -> 60 | D4: =Inputs!C17 -> 60 | E4: =Inputs!C17 -> 60 | F4: =Inputs!$C17 -> 60 | G4: =Inputs!$C17 -> 60 | H4: =Inputs!$C17 -> 60 | I4: =Inputs!$C17 -> 60
A5: PeakRpsInput | B5: Пиковый RPS (если задан напрямую) | C5: =Inputs!C4 -> 0 | D5: =Inputs!C4 -> 0 | E5: =Inputs!C4 -> 0 | F5: =Inputs!$C4 -> 0 | G5: =Inputs!$C4 -> 0 | H5: =Inputs!$C4 -> 0 | I5: =Inputs!$C4 -> 0
A6: HeadroomPct | B6: Запас по производительности, % | C6: =Inputs!C5 -> 25 | D6: =Inputs!C5 -> 25 | E6: =Inputs!C5 -> 25 | F6: =Inputs!$C5 -> 25 | G6: =Inputs!$C5 -> 25 | H6: =Inputs!$C5 -> 25 | I6: =Inputs!$C5 -> 25
A7: GatewayEnabled | B7: Gateway включен (0/1) | C7: =Inputs!C7 -> 1 | D7: =Inputs!C7 -> 1 | E7: =Inputs!C7 -> 1 | F7: =Inputs!$C7 -> 1 | G7: =Inputs!$C7 -> 1 | H7: =Inputs!$C7 -> 1 | I7: =Inputs!$C7 -> 1
A8: GatewayOverheadPct | B8: Надбавка Gateway, % | C8: =Inputs!C8 -> 10 | D8: =Inputs!C8 -> 10 | E8: =Inputs!C8 -> 10 | F8: =Inputs!$C8 -> 10 | G8: =Inputs!$C8 -> 10 | H8: =Inputs!$C8 -> 10 | I8: =Inputs!$C8 -> 10
A9: AccountingEnabled | B9: Аккаунтинг включен (0/1) | C9: =Inputs!$C10 -> 1 | D9: =Inputs!$C10 -> 1 | E9: =Inputs!$C10 -> 1 | F9: 1 | G9: 1 | H9: 1 | I9: =Inputs!$C10 -> 1
A10: OcspEnabled | B10: OCSP включен (0/1) | C10: =Inputs!$C9 -> 1 | D10: N/A | E10: N/A | F10: N/A | G10: N/A | H10: N/A | I10: =Inputs!$C9 -> 1
A11: OcspOverheadPct | B11: Надбавка OCSP, % | C11: =Coefficients!C5 -> 14 | D11: N/A | E11: N/A | F11: N/A | G11: N/A | H11: N/A | I11: 39
A12: AuthAttemptsPerDevicePerDay | B12: Количество подключений каждого устройства в день | C12: =Inputs!$C13 -> 2 | D12: =Inputs!$C13 -> 2 | E12: =Inputs!$C13 -> 2 | F12: =Inputs!$C13 -> 2 | G12: =Inputs!$C13 -> 2 | H12: =Inputs!$C13 -> 2 | I12: =Inputs!$C13 -> 2
A13: Retention_days | B13: Период сохранения данных в БД, дней | C13: =Inputs!$C14 -> 14 | D13: =Inputs!$C14 -> 14 | E13: =Inputs!$C14 -> 14 | F13: =Inputs!$C14 -> 14 | G13: =Inputs!$C14 -> 14 | H13: =Inputs!$C14 -> 14 | I13: =Inputs!$C14 -> 14
A16: ConcurrentDevices | B16: Количество одновременных устройств | C16: =C2*C3/100 -> 2400 | D16: =C2*C3/100 -> 2400 | E16: =C2*C3/100 -> 2400 | F16: =D2*D3/100 -> 2400 | G16: =E2*E3/100 -> 2400 | H16: =F2*F3/100 -> 2400 | I16: =G2*G3/100 -> 2400
A17: RpsFromDevices | B17: RPS, рассчитанный из Devices/Concurrent/Burst | C17: =C16/C4 -> 40 | D17: =D16/D4 -> 40 | E17: =E16/E4 -> 40 | F17: =F16/F4 -> 40 | G17: =G16/G4 -> 40 | H17: =H16/H4 -> 40 | I17: =I16/I4 -> 40
A18: BasePeakRps | B18: Базовый пиковый RPS (max из заданного и рассчитанного) | C18: =IF(C5>0,MAX(C5,C17),C17) -> 40 | D18: =IF(C5>0,MAX(C5,C17),C17) -> 40 | E18: =IF(C5>0,MAX(C5,C17),C17) -> 40 | F18: =IF(D5>0,MAX(D5,D17),D17) -> 40 | G18: =IF(E5>0,MAX(E5,E17),E17) -> 40 | H18: =IF(H5>0,MAX(H5,H17),H17) -> 40 | I18: =IF(I5>0,MAX(I5,I17),I17) -> 40
A19: RpsWithGw | B19: RPS с учётом Gateway | C19: =IF(C7=1,C18*(1+C8/100),C18) -> 44 | D19: =IF(D7=1,D18*(1+D8/100),D18) -> 44 | E19: =IF(E7=1,E18*(1+E8/100),E18) -> 44 | F19: =IF(F7=1,F18*(1+F8/100),F18) -> 44 | G19: =IF(G7=1,G18*(1+G8/100),G18) -> 44 | H19: =IF(H7=1,H18*(1+H8/100),H18) -> 44 | I19: =IF(I7=1,I18*(1+I8/100),I18) -> 44
A20: TargetRpsBase | B20: RPS с учётом Headroom (без OCSP) | C20: =C19*(1+C6/100) -> 55 | D20: =D19*(1+D6/100) -> 55 | E20: =E19*(1+E6/100) -> 55 | F20: =F19*(1+F6/100) -> 55 | G20: =G19*(1+G6/100) -> 55 | H20: =H19*(1+H6/100) -> 55 | I20: =I19*(1+I6/100) -> 55
A21: TargetRpsAccountingBase | B21: RPS с учетом аккаунтинга (если включен) | C21: =IF(C9=1,C20/Coefficients!$C33,C20) -> 67.5 | D21: =IF(D9=1,D20/Coefficients!$C33,D20) -> 67.5 | E21: =IF(E9=1,E20/Coefficients!$C33,E20) -> 67.5 | F21: =IF(F9=1,F20/Coefficients!$C33,F20) -> 67.5 | G21: =IF(G9=1,G20/Coefficients!$C33,G20) -> 67.5 | H21: =IF(H9=1,H20/Coefficients!$C33,H20) -> 67.5 | I21: =IF(I9=1,I20/Coefficients!$C33,I20) -> 67.5
A22: TargetRpsEffective | B22: Итоговый RPS (с учётом OCSP, если включен) | C22: =IF(C10=1,C21*(1+C11/100),C21) -> 76.95 | D22: =IF(D10=1,D21*(1+D11/100),D21) -> 67.5 | E22: =IF(E10=1,E21*(1+E11/100),E21) -> 67.5 | F22: =IF(F10=1,F21*(1+F11/100),F21) -> 67.5 | G22: =IF(G10=1,G21*(1+G11/100),G21) -> 67.5 | H22: =IF(H10=1,H21*(1+H11/100),H21) -> 67.5 | I22: =IF(I10=1,I21*(1+I11/100),I21) -> 93.825
A25: Scenario1_PodsCalculated | B25: Расчётное количество pod (до минимума) | C25: =ROUNDUP(C22/Coefficients!C2,0) -> 4 | D25: =ROUNDUP(D22/Coefficients!C14,0) -> 3 | E25: =ROUNDUP(E22/Coefficients!C17,0) -> 6 | F25: =ROUNDUP(F22/Coefficients!C23,0) -> 4 | G25: =ROUNDUP(G22/(Coefficients!$C14),0) -> 3 | H25: =ROUNDUP(H22/(Coefficients!$C17),0) -> 6 | I25: =ROUNDUP(I22/(Coefficients!$C20),0) -> 13
A26: Scenario1_MinPods | B26: Минимальное количество pod | C26: =3 -> 3 | D26: 3 | E26: 4 | F26: 3 | G26: 3 | H26: 3 | I26: 6
A27: Scenario1_PodsFinal | B27: Итоговое количество pod | C27: =CEILING(MAX(C25,C26)/ Inputs!$C12, 1) * Inputs!$C12 -> 6 | D27: =CEILING(MAX(D25,D26)/ Inputs!$C12, 1) * Inputs!$C12 -> 3 | E27: =CEILING(MAX(E25,E26)/ Inputs!$C12, 1) * Inputs!$C12 -> 6 | F27: =CEILING(MAX(F25,F26)/ Inputs!$C12, 1) * Inputs!$C12 -> 6 | G27: =CEILING(MAX(G25,G26)/ Inputs!$C12, 1) * Inputs!$C12 -> 3 | H27: =CEILING(MAX(H25,H26)/ Inputs!$C12, 1) * Inputs!$C12 -> 6 | I27: =CEILING(MAX(I25,I26)/ Inputs!$C12, 1) * Inputs!$C12 -> 15
A28: Scenario1_RpsPerPod | B28: Фактический RPS на pod | C28: =C22/C27 -> 12.825 | D28: =D22/D27 -> 22.5 | E28: =E22/E27 -> 11.25 | F28: =F22/F27 -> 11.25 | G28: =G22/G27 -> 22.5 | H28: =H22/H27 -> 11.25 | I28: =I22/I27 -> 6.255
A30: Scenario1_PodCpuLimitCores | B30: Лимит CPU (cores) на pod | C30: =C28*Coefficients!C3*Coefficients!C6 -> 1.4428125 | D30: =D28*Coefficients!C15*Coefficients!C6 -> 2.4949687 | E30: =E28*Coefficients!$C18*Coefficients!$C6 -> 2.953125 | F30: =F28*Coefficients!C24*Coefficients!C6 -> 1.96875 | G30: =G28*Coefficients!C27*Coefficients!C6 -> 3.09375 | H30: =H28*Coefficients!$C18*Coefficients!$C6 -> 2.953125 | I30: =I28*Coefficients!$C21*Coefficients!$C6*IF(I9=1,Coefficients!C29) -> 2.2119244
A31: Scenario1_PodCpuLimit_mCPU | B31: Лимит CPU (mCPU) на pod | C31: =ROUNDUP(C30*1000,10) -> 1442.8125 | D31: =ROUNDUP(D30*1000,10) -> 2494.9688 | E31: =ROUNDUP(E30*1000,10) -> 2953.125 | F31: =ROUNDUP(F30*1000,10) -> 1968.75 | G31: =ROUNDUP(G30*1000,10) -> 3093.75 | H31: =ROUNDUP(H30*1000,10) -> 2953.125 | I31: =ROUNDUP(I30*1000,10) -> 2211.9244
A32: Scenario1_PodMemLimitMiB | B32: Лимит памяти (MiB) на pod | C32: =MAX(1024,CEILING(C28*Coefficients!C4*Coefficients!C6,64)) -> 1024 | D32: =MAX(1024,CEILING(D28*Coefficients!C16*Coefficients!C6,64)) -> 1024 | E32: =MAX(1024,CEILING(E28*Coefficients!$C19*Coefficients!$C6,64)) -> 1024 | F32: =MAX(1024,CEILING(F28*Coefficients!C25*Coefficients!C6,64)) -> 1024 | G32: =MAX(1024,CEILING(G28*Coefficients!C16*Coefficients!C6*Coefficients!C30,64)) -> 1152 | H32: =MAX(1024,CEILING(H28*Coefficients!$C19*Coefficients!$C6,64)) -> 1024 | I32: =MAX(1024,CEILING(I28*Coefficients!$C22*Coefficients!$C6*IF(I9=1,Coefficients!C30),64)) -> 1024
A33: Scenario1_PodCpuRequest_mCPU | B33: Request CPU (mCPU) на pod | C33: =ROUNDUP(C31*0.6,10) -> 865.6875 | D33: =ROUNDUP(D31*0.6,10) -> 1496.9813 | E33: =ROUNDUP(E31*0.6,10) -> 1771.875 | F33: =ROUNDUP(F31*0.6,10) -> 1181.25 | G33: =ROUNDUP(G31*0.6,10) -> 1856.25 | H33: =ROUNDUP(H31*0.6,10) -> 1771.875 | I33: =ROUNDUP(I31*0.6,10) -> 1327.1546
A34: Scenario1_PodMemRequestMiB | B34: Request памяти (MiB) на pod | C34: =CEILING(C32*0.6,64) -> 640 | D34: =CEILING(D32*0.6,64) -> 640 | E34: =CEILING(E32*0.6,64) -> 640 | F34: =CEILING(F32*0.6,64) -> 640 | G34: =CEILING(G32*0.6,64) -> 704 | H34: =CEILING(H32*0.6,64) -> 640 | I34: =CEILING(I32*0.6,64) -> 640
A36: Scenario1_DcTotalCpu_mCPU | B36: Суммарный лимит CPU (mCPU) подов в одном ЦОД | C36: =C27*C31 -> 8656.875 | D36: =D27*D31 -> 7484.9062 | E36: =E27*E31 -> 17718.75 | F36: =F27*F31 -> 11812.5 | G36: =G27*G31 -> 9281.25 | H36: =H27*H31 -> 17718.75 | I36: =I27*I31 -> 33178.866
A37: Scenario1_DcTotalCpuCores | B37: Суммарный лимит CPU (cores) подов в одном ЦОД | C37: =C36/1000 -> 8.656875 | D37: =D36/1000 -> 7.4849062 | E37: =E36/1000 -> 17.71875 | F37: =F36/1000 -> 11.8125 | G37: =G36/1000 -> 9.28125 | H37: =H36/1000 -> 17.71875 | I37: =I36/1000 -> 33.178866
A38: Scenario1_DcTotalMemMiB | B38: Суммарный лимит памяти (MiB) подов в одном ЦОД | C38: =C27*C32 -> 6144 | D38: =D27*D32 -> 3072 | E38: =E27*E32 -> 6144 | F38: =F27*F32 -> 6144 | G38: =G27*G32 -> 3456 | H38: =H27*H32 -> 6144 | I38: =I27*I32 -> 15360
A39: Scenario1_DcTotalMemGiB | B39: Суммарный лимит памяти (GiB) подов в одном ЦОД | C39: =C38/1024 -> 6 | D39: =D38/1024 -> 3 | E39: =E38/1024 -> 6 | F39: =F38/1024 -> 6 | G39: =G38/1024 -> 3.375 | H39: =H38/1024 -> 6 | I39: =I38/1024 -> 15
A40: Scenario1_DcCpuCoresWithUtil | B40: CPU с учётом целевой загрузки нод | C40: =C37/Coefficients!C7 -> 12.366964 | D40: =D37/Coefficients!C7 -> 10.692723 | E40: =E37/Coefficients!$C7 -> 25.3125 | F40: =F37/Coefficients!C7 -> 16.875 | G40: =G37/Coefficients!C7 -> 13.258929 | H40: =H37/Coefficients!$C7 -> 25.3125 | I40: =I37/Coefficients!$C7 -> 47.398379
A41: Scenario1_DcMemGiBWithUtil | B41: Память (GiB) с учётом целевой загрузки нод | C41: =C39/Coefficients!C7 -> 8.5714286 | D41: =D39/Coefficients!C7 -> 4.2857143 | E41: =E39/Coefficients!$C7 -> 8.5714286 | F41: =F39/Coefficients!C7 -> 8.5714286 | G41: =G39/Coefficients!C7 -> 4.8214286 | H41: =H39/Coefficients!$C7 -> 8.5714286 | I41: =I39/Coefficients!$C7 -> 21.428571
A43: Scenario1_NodeMemSizeGib | B43: Сырое значение памяти на ноду + бейзлайн | C43: =(C27*C32/Inputs!$C12/1024+Coefficients!$C$13)*Coefficients!$C8 -> 19.32 | D43: =(D27*D32/Inputs!$C12/1024+Coefficients!$C$13)*Coefficients!$C8 -> 18.17 | E43: =(E27*E32/Inputs!$C12/1024+Coefficients!$C$13)*Coefficients!$C8 -> 19.32 | F43: =(F27*F32/Inputs!$C12/1024+Coefficients!$C$13)*Coefficients!$C8 -> 19.32 | G43: =(G27*G32/Inputs!$C12/1024+Coefficients!$C$13)*Coefficients!$C8 -> 18.31375 | H43: =(H27*H32/Inputs!$C12/1024+Coefficients!$C$13)*Coefficients!$C8 -> 19.32 | I43: =(I27*I32/Inputs!$C12/1024+Coefficients!$C$13)*Coefficients!$C8 -> 22.77
B44: Количество занятой памяти в таблице, Гб (количество сессий * количество дней retention period * память на сессию одного устройства в байтах * количество устройств) | C44: =(Coefficients!C39+IF(C10=1,Coefficients!C34)+IF(C10=1,Coefficients!C41))*C12*C13*C2/1024/1024/1024 -> 7.7138573 | D44: =Coefficients!C35*D12*D13*D2/1024/1024/1024 -> 1.9292831 | E44: =Coefficients!C38*E12*E13*E2/1024/1024/1024 -> 9.3631148 | F44: =(Coefficients!$C$34+Coefficients!$C$35+Coefficients!$C$37)*F12*F13*F2/1024/1024/1024 -> 6.0046017 | G44: =(Coefficients!$C$34+Coefficients!$C$35)*G12*G13*G2/1024/1024/1024 -> 2.037555 | H44: =(Coefficients!C34+Coefficients!C38)*H12*H13*H2/1024/1024/1024 -> 9.4713867 | I44: =(Coefficients!C40+IF(C10=1,Coefficients!C34)+IF(I10=1,Coefficients!C41))*I12*I13*I2/1024/1024/1024 -> 35.341117

Sheet Расчеты_МАВ
A1: Devices max | B1: Target RPS (с запасами) | C1: Pods min при 27 RPS/pod
A2: 5 000 | B2: 34.375 | C2: 2
A3: 10 000 | B3: 68.75 | C3: 3
A4: 12 000 | B4: 82.5 | C4: 4
A5: 15 000 | B5: 103.125 | C5: 4
A6: 20 000 | B6: 137.5 | C6: 6

Sheet Калькулятор
A1: ProfileName | B1: Типовой профиль по количеству устройств | C1: =IF('Вычисления'!C2<=5000,"EAP-TLS: A: до 5k устройств",IF('Вычисления'!C2<=10000,"EAP-TLS: B: 5k–10k",IF('Вычисления'!C2<=12000,"EAP-TLS: C: 10k–12k",IF('Вычисления'!C2<=15000,"EAP-TLS: D: 12k–15k",IF('Вычисления'!C2<=20000,"EAP-TLS: E: 15k–20k","EAP-TLS: Вне типовых профилей"))))) -> EAP-TLS: B: 5k–10k | D1: =IF('Вычисления'!D2<=5000,"MAB: A: до 5k устройств",IF('Вычисления'!D2<=10000,"MAB: B: 5k–10k",IF('Вычисления'!D2<=12000,"MAB: C: 10k–12k",IF('Вычисления'!D2<=15000,"MAB: D: 12k–15k",IF('Вычисления'!D2<=20000,"MAB: E: 15k–20k","MAB: Вне типовых профилей"))))) -> MAB: B: 5k–10k | E1: =IF('Вычисления'!C2<=5000,"PEAP: A: до 5k устройств",IF('Вычисления'!C2<=10000,"PEAP: B: 5k–10k",IF('Вычисления'!C2<=12000,"PEAP: C: 10k–12k",IF('Вычисления'!C2<=15000,"PEAP: D: 12k–15k",IF('Вычисления'!C2<=20000,"PEAP: E: 15k–20k","PEAP: Вне типовых профилей"))))) -> PEAP: B: 5k–10k | F1: MAB + Аккаунтинг + MAC-spoofing | G1: MAB+Acct | H1: PEAP+Acct | I1: TEAP+Acct
A2: Profile_MinPods | B2: Минимальное количество pod | C2: ='Вычисления'!C26 -> 3 | D2: ='Вычисления'!D26 -> 3 | E2: ='Вычисления'!E26 -> 4 | F2: ='Вычисления'!F26 -> 3 | G2: ='Вычисления'!G26 -> 3 | H2: ='Вычисления'!H26 -> 3 | I2: ='Вычисления'!I26 -> 6 | K2: Таблица CPU классов нод | L2: аблица RAM классов нод (GiB)
A3: Profile_RecommendedPods | B3: Рекомендуемое количество pod | C3: =CEILING('Вычисления'!C27 / C10, 1) * C10 -> 6 | D3: =CEILING('Вычисления'!D27 / D10, 1) * D10 -> 3 | E3: =CEILING('Вычисления'!E27 / E10, 1) * E10 -> 6 | F3: =CEILING('Вычисления'!F27 / F10, 1) * F10 -> 6 | G3: =CEILING('Вычисления'!G27 / G10, 1) * G10 -> 3 | H3: =CEILING('Вычисления'!H27 / H10, 1) * H10 -> 6 | I3: =CEILING('Вычисления'!I27 / I10, 1) * I10 -> 15 | K3: 8
A4: Required_NodeCpuCores | B4: Сырое значение CPU на ноду | C4: =C13*C3/C10+Coefficients!C11 -> 7.985625 | D4: =D13*D3/D10+Coefficients!C9 -> 6.4949687 | E4: =E13*E3/E10+Coefficients!C10 -> 9.90625 | F4: =F13*F3/F10+Coefficients!C10 -> 7.9375 | G4: =G13*G3/G10+Coefficients!$C10 -> 7.09375 | H4: =H13*H3/H10+Coefficients!$C10 -> 9.90625 | I4: =I13*I3/I10+Coefficients!$C12 -> 16.059622 | K4: 12 | L4: 24
A5: Profile_NodeCpuCores | B5: CPU на ноду (vCPU, профиль) | C5: =IFERROR( XLOOKUP( C4, $K$2:$K$5, $K$2:$K$5, , 1), "--" ) -> 8 | D5: =IFERROR( XLOOKUP( D4, $K$2:$K$5, $K$2:$K$5, , 1), "--" ) -> 8 | E5: =IFERROR( XLOOKUP( E4, $K$2:$K$5, $K$2:$K$5, , 1), "--" ) -> 12 | F5: =IFERROR( XLOOKUP( F4, $K$2:$K$5, $K$2:$K$5, , 1), "--" ) -> 8 | G5: =IFERROR( XLOOKUP( G4, $K$2:$K$5, $K$2:$K$5, , 1), "--" ) -> 8 | H5: =IFERROR( XLOOKUP( H4, $K$2:$K$5, $K$2:$K$5, , 1), "--" ) -> 12 | I5: {=IFERROR( XLOOKUP( I4, $K$2:$K$7, $K$2:$K$7, , 1), "--" )} -> 24 | K5: 16 | L5: 32
A6: Required_NodeMemGiB | B6: Сырое значение памяти на ноду + бейзлайн | C6: =(C15*C3/C10/1024+Coefficients!$C$13)*Coefficients!$C8 -> 19.32 | D6: =(D15*D3/D10/1024+Coefficients!$C$13)*Coefficients!$C8 -> 18.17 | E6: =(E15*E3/E10/1024+Coefficients!$C$13)*Coefficients!$C8 -> 19.32 | F6: =(F15*F3/F10/1024+Coefficients!$C$13)*Coefficients!$C8 -> 19.32 | G6: =(G15*G3/G10/1024+Coefficients!$C$13)*Coefficients!$C8 -> 18.31375 | H6: =(H15*H3/H10/1024+Coefficients!$C$13)*Coefficients!$C8 -> 19.32 | I6: =(I15*I3/I10/1024+Coefficients!$C$13)*Coefficients!$C8 -> 22.77 | K6: 24 | L6: 48
A7: Required_NodeMemGiB | B7: Память на ноду с учетом других сервисов | C7: =IF('Вычисления'!C2<=5000, MAX(24, 'Вычисления'!C43), IF('Вычисления'!C2<=10000, MAX(32, 'Вычисления'!C43), IF('Вычисления'!C2<=15000, MAX(48, 'Вычисления'!C43), IF('Вычисления'!C2<=20000, MAX(48, 'Вычисления'!C43), "--")))) -> 32 | D7: =IF('Вычисления'!D2<=5000, MAX(24, 'Вычисления'!D43), IF('Вычисления'!D2<=10000, MAX(32, 'Вычисления'!D43), IF('Вычисления'!D2<=20000, MAX(48, 'Вычисления'!D43), "--"))) -> 32 | E7: =IF('Вычисления'!E2<=5000, MAX(24, 'Вычисления'!E43), IF('Вычисления'!E2<=10000, MAX(32, 'Вычисления'!E43), IF('Вычисления'!E2<=15000, MAX(48, 'Вычисления'!E43), IF('Вычисления'!E2<=20000, MAX(64, 'Вычисления'!E43), "--")))) -> 32 | F7: =IF('Вычисления'!F2<=5000, MAX(24, 'Вычисления'!F43), IF('Вычисления'!F2<=10000, MAX(32, 'Вычисления'!F43), IF('Вычисления'!F2<=15000, MAX(48, 'Вычисления'!F43), IF('Вычисления'!F2<=20000, MAX(64, 'Вычисления'!F43), "--")))) -> 32 | G7: =IF('Вычисления'!G2<=5000, MAX(24, 'Вычисления'!G43), IF('Вычисления'!G2<=10000, MAX(32, 'Вычисления'!G43), IF('Вычисления'!G2<=15000, MAX(48, 'Вычисления'!G43), IF('Вычисления'!G2<=20000, MAX(64, 'Вычисления'!G43), "--")))) -> 32 | H7: =IF('Вычисления'!H2<=5000, MAX(24, 'Вычисления'!H43), IF('Вычисления'!H2<=10000, MAX(32, 'Вычисления'!H43), IF('Вычисления'!H2<=15000, MAX(48, 'Вычисления'!H43), IF('Вычисления'!H2<=20000, MAX(64, 'Вычисления'!H43), "--")))) -> 32 | I7: =IF('Вычисления'!I2<=5000, MAX(24, 'Вычисления'!I43), IF('Вычисления'!I2<=10000, MAX(32, 'Вычисления'!I43), IF('Вычисления'!I2<=15000, MAX(48, 'Вычисления'!I43), IF('Вычисления'!I2<=20000, MAX(64, 'Вычисления'!I43), "--")))) -> 32 | K7: 32 | L7: 64
A8: NodeStorageGb | B8: Хранилище на ноду (Gb, дефолтное значение) | C8: 120 | D8: 120 | E8: 120 | F8: 120 | G8: 120 | H8: 120 | I8: 120
A9: RadAuthStorageGb | B9: Из них данных по сессиям (Gb) | C9: ='Вычисления'!C44 -> 7.7138573 | D9: ='Вычисления'!D44 -> 1.9292831 | E9: ='Вычисления'!E44 -> 9.3631148 | F9: ='Вычисления'!F44 -> 6.0046017 | G9: ='Вычисления'!G44 -> 2.037555 | H9: ='Вычисления'!H44 -> 9.4713867 | I9: ='Вычисления'!I44 -> 35.341117
A10: NodeNumber | B10: Количество нод в кластере (задается на листе Inputs) | C10: =Inputs!C12 -> 3 | D10: =Inputs!C12 -> 3 | E10: =Inputs!C12 -> 3 | F10: =Inputs!$C12 -> 3 | G10: =Inputs!$C12 -> 3 | H10: =Inputs!$C12 -> 3 | I10: =Inputs!$C12 -> 3
A11: Profile_ClusterCpuCores | B11: Общее количество CPU на кластер (vCPU, профиль) | C11: =C5*C10 -> 24 | D11: =D5*D10 -> 24 | E11: =E5*E10 -> 36 | F11: =F5*F10 -> 24 | G11: =G5*G10 -> 24 | H11: =H5*H10 -> 36 | I11: =I5*I10 -> 72
A12: Profile_ClusterMemGib | B12: Общее количество RAM на кластер (GiB, профиль) | C12: =C7*C10 -> 96 | D12: =D7*D10 -> 96 | E12: =E7*E10 -> 96 | F12: =F7*F10 -> 96 | G12: =G7*G10 -> 96 | H12: =H7*H10 -> 96 | I12: =I7*I10 -> 96
A13: PodCpuLimitCores | B13: Лимит CPU (cores) на pod | C13: ='Вычисления'!C30 -> 1.4428125 | D13: ='Вычисления'!D30 -> 2.4949687 | E13: ='Вычисления'!E30 -> 2.953125 | F13: ='Вычисления'!F30 -> 1.96875 | G13: ='Вычисления'!G30 -> 3.09375 | H13: ='Вычисления'!H30 -> 2.953125 | I13: ='Вычисления'!I30 -> 2.2119244
A14: PodCpuLimit_mCPU | B14: Лимит CPU (mCPU) на pod | C14: =ROUNDUP(C13*1000,10) -> 1442.8125 | D14: =ROUNDUP(D13*1000,10) -> 2494.9688 | E14: =ROUNDUP(E13*1000,10) -> 2953.125 | F14: =ROUNDUP(F13*1000,10) -> 1968.75 | G14: =ROUNDUP(G13*1000,10) -> 3093.75 | H14: =ROUNDUP(H13*1000,10) -> 2953.125 | I14: =ROUNDUP(I13*1000,10) -> 2211.9244
A15: PodMemLimitMiB | B15: Лимит памяти (MiB) на pod | C15: ='Вычисления'!C32 -> 1024 | D15: ='Вычисления'!D32 -> 1024 | E15: ='Вычисления'!E32 -> 1024 | F15: ='Вычисления'!F32 -> 1024 | G15: ='Вычисления'!G32 -> 1152 | H15: ='Вычисления'!H32 -> 1024 | I15: ='Вычисления'!I32 -> 1024
A16: PodCpuRequest_mCPU | B16: Request CPU (mCPU) на pod | C16: =ROUNDUP(C14*0.6,10) -> 865.6875 | D16: =ROUNDUP(D14*0.6,10) -> 1496.9813 | E16: =ROUNDUP(E14*0.6,10) -> 1771.875 | F16: =ROUNDUP(F14*0.6,10) -> 1181.25 | G16: =ROUNDUP(G14*0.6,10) -> 1856.25 | H16: =ROUNDUP(H14*0.6,10) -> 1771.875 | I16: =ROUNDUP(I14*0.6,10) -> 1327.1546
A17: PodMemRequestMiB | B17: Request памяти (MiB) на pod | C17: =CEILING(C15*0.6,64) -> 640 | D17: =CEILING(D15*0.6,64) -> 640 | E17: =CEILING(E15*0.6,64) -> 640 | F17: =CEILING(F15*0.6,64) -> 640 | G17: =CEILING(G15*0.6,64) -> 704 | H17: =CEILING(H15*0.6,64) -> 640 | I17: =CEILING(I15*0.6,64) -> 640

Sheet Результаты измерений
A1: Тест № | B1: Дата тестирования | C1: Сценарий | D1: Профиль нагрузки | E1: Начало теста (Т0) | F1: Конец теста (Т1) | G1: Planned RPS | H1: Auth Requests (increase) | I1: CPU Throttling max per pod (%) | J1: CPU Throttling avg across pods (%) | K1: Run-queue (node load1 / CPU) peak | L1: Pod Working Set Δ max (MiB) | M1: UDP drops/errors per pod (sum) | N1: UDP drops/errors per node (sum) | O1: Per-pod RPS p50 | P1: Per-pod RPS p95 | Q1: LB imbalance (CV) | R1: Actual CPU Limit (mCPU) | S1: Actual CPU Request (mCPU) | T1: Memory Limit (MiB) | U1: Memory Request (MiB) | V1: Max VUS | W1: Итераций (всего) | X1: Dropped итераций | Y1: Успешных аутентификаций | Z1: Success Rate (%) | AA1: Неудачных аутентификаций | AB1: Failure Rate (%) | AC1: Таймауты | AD1: Timeout Rate (%) | AE1: Ошибки валидации сертификата | AF1: Cert Validation Errors (%) | AG1: Auth Duration (avg, ms) | AH1: Auth Duration P95 (ms) | AI1: Auth Duration Max (ms) | AJ1: Iteration Duration (avg, ms) | AK1: Iteration Duration Max (ms) | AL1: Количество подов | AM1: Client Peak RPS (система) | AN1: Client Peak RPS per pod | AO1: Pod CPU Peak (cores) | AP1: Pod CPU Peak (mCPU) | AQ1: Pod Memory Peak (MiB) | AR1: Node CPU Utilization Peak (%) | AS1: Node Memory Utilization Peak (%) | AT1: CPU Limit Recommended (mCPU) | AU1: Memory Limit Recommended (MiB) | AV1: CPU Request Recommended (mCPU) | AW1: Memory Request Recommended (MiB) | AX1: Статус | AY1: Ссылка на дашборд | AZ1: Ссылка на снэпшот дашборда | BA1: Примечание | BB1: Команда для запуска | BC1: Уникальных пользователей | BD1: Уникальных NAS-IP | BE1: MAC-адресов | BF1: Количество нод | BG1: CPU на ноду | BH1: RAM на ноду | BI1: Storage на ноду
A2: old_1 | B2: 45961 | C2: EAP-TLS | D2: 1m@30,1m@100,1m@200,2m@50,1m@0 | E2: 45961.724 | F2: 45961.729 | G2: 200 | H2: 200003 | I2: 0.965 | J2: 0.9 | K2: 0.886 | L2: 629 | M2: 0 | N2: 0 | R2: 2500 | S2: 150 | T2: 3000 | U2: 300 | V2: 3000 | W2: 30299 | X2: 0 | Y2: 22491 | Z2: =Y2/(W2+X2) -> 0.74230173 | AA2: 7808 | AB2: =AA2/W2 -> 0.25769827 | AC2: 682 | AD2: =AC2/W2 -> 0.022508994 | AE2: 1271 | AF2: 3.53 | AG2: 4420 | AH2: 16970 | AI2: 20120 | AJ2: 4436.27 | AK2: 20896.91 | AL2: 6 | AM2: 285 | AN2: 47.5 | AO2: 2.446 | AP2: =AO2*1000 -> 2446 | AQ2: 1004 | AR2: 51.9 | AS2: 29.65 | AT2: =AP2*1.25 -> 3057.5 | AU2: =1.25*AQ2 -> 1255 | AV2: =AP2*0.65 -> 1589.9 | AW2: =AQ2*0.65 -> 652.6 | AX2: ⚠️ Требует анализа | AY2: https://10.116.41.195/grafana/d/edo-radius-full/edo-radius3a-full-auth-acct-2b-kafka-2b-infra?orgId=1&from=1761920400000&to=1761921179000 | AZ2: screencapture-10-116-41-195-grafana-d-edo-radius-full-edo-radius3a-full-auth-acct-2b-kafka-2b-infra-2025-10-31-19_00_21.pdf | BA2: High auth failure rate (21.7%), cert validation issues (3.5%), auth timeouts (1.9%) | BB2: CSV_PATH=./users-10.csv TLS_PFX_DIR=./certs-eap-tls TLS_PFX_EXT=.pfx PRIVATE_KEY_PASS=12345 TLS_MAC_FILE=./macs.txt EAPOL_NAS_IP_LIST="10.116.42.70,10.116.42.71,10.116.42.72,10.116.42.73,10.116.42.74,10.116.42.75,10.116.42.76,10.116.42.77,10.116.42.78,10.116.42.79" RADIUS_ADDRS="10.116.41.195" RADIUS_SECRET=cisco CA_CERT=./ROOT_WIN-AD.cer TLS_STAGES="1m@30,1m@100,1m@200,2m@50,1m@0" TLS_VUS=3000 TLS_MAXVUS=6000 EAPOL_TIMEOUT_SEC=20 EXEC_TIMEOUT_SEC=30 ERROR_LOG=./tls_errors.log LOG_ALL_FAILURES=true RPS_SECOND_STATS=true EAPOL_BIN=./eapol_test_2.11 k6-exec run radius_load_tls.js | BC2: 10 | BD2: 11 | BE2: 10000 | BF2: 3 | BG2: 16 | BH2: 64 | BI2: 120
A3: old_2 | B3: 45962 | C3: EAP-TLS | D3: 1m@10,1m@30,1m@65,2m@16,1m@0 | G3: 65 | R3: 2500 | S3: 150 | T3: 3000 | U3: 300 | V3: 1000 | W3: 9689 | X3: 0 | Y3: 9689 | Z3: =Y3/(W3+X3) -> 1 | AA3: 0 | AB3: =AA3/W3 -> 0 | AC3: 0 | AD3: =AC3/W3 -> 0 | AE3: 0 | AF3: 0 | AG3: 135 | AH3: 167 | AI3: 3130 | AJ3: 137.3 | AK3: 3132.6 | AL3: 6 | AM3: 67 | AN3: =AM3/6 -> 11.166667 | AO3: 1.89 | AP3: =AO3*1000 -> 1890 | AQ3: 775 | AR3: 42.87 | AS3: 29.08 | AT3: =AP3*1.25 -> 2362.5 | AU3: =1.25*AQ3 -> 968.75 | AV3: =AP3*0.65 -> 1228.5 | AW3: =AQ3*0.65 -> 503.75 | AX3: Есть разбалансировка, один под жрет гораздо больше остальных ресурсов и обрабатывает гораздо больший трафик | AY3: https://10.116.41.195/grafana/d/edo-radius-full/edo-radius3a-full-auth-acct-2b-kafka-2b-infra?orgId=1&from=1761982980000&to=1761983399000 | AZ3: screencapture-10-116-41-195-grafana-d-edo-radius-full-edo-radius3a-full-auth-acct-2b-kafka-2b-infra-2025-11-01-11_20_21.pdf | BA3: Сильный дисбаланс подов | BB3: CSV_PATH=./users-10.csv TLS_PFX_DIR=./certs-eap-tls TLS_PFX_EXT=.pfx PRIVATE_KEY_PASS=12345 TLS_MAC_FILE=./macs.txt EAPOL_NAS_IP_LIST="10.116.42.70,10.116.42.71,10.116.42.72,10.116.42.73,10.116.42.74,10.116.42.75,10.116.42.76,10.116.42.77,10.116.42.78,10.116.42.79" RADIUS_ADDRS="10.116.41.195" RADIUS_SECRET=cisco CA_CERT=./ROOT_WIN-AD.cer TLS_STAGES="1m@10,1m@30,1m@65,2m@16,1m@0" TLS_VUS=1000 TLS_MAXVUS=6000 EAPOL_TIMEOUT_SEC=20 EXEC_TIMEOUT_SEC=30 ERROR_LOG=./tls_errors.log LOG_ALL_FAILURES=true RPS_SECOND_STATS=true EAPOL_BIN=./eapol_test_2.11 k6-exec run radius_load_tls.js | BC3: 10 | BD3: 11 | BE3: 10000 | BF3: 3 | BG3: 16 | BH3: 64 | BI3: 120
A4: old_3 | B4: 45962 | C4: EAP-TLS | D4: 1m@120,3m@200,1m@0 | G4: 200 | R4: 2500 | S4: 150 | T4: 3000 | U4: 300 | V4: 1200 | W4: 14845 | X4: 0 | Y4: 14777 | Z4: =Y4/(W4+X4) -> 0.99541933 | AA4: 68 | AB4: =AA4/W4 -> 0.0045806669 | AC4: 68 | AD4: =AC4/W4 -> 0.0045806669 | AE4: 0 | AF4: 0 | AG4: 7500 | AH4: 22200 | AI4: 61370 | AJ4: 20314.54 | AK4: 109258.21 | AL4: 6 | AM4: 75 | AN4: =AM4/AL4 -> 12.5 | AO4: 2.168 | AP4: =AO4*1000 -> 2168 | AQ4: 796 | AR4: 48.49 | AS4: 28.96 | AT4: =AP4*1.25 -> 2710 | AU4: =1.25*AQ4 -> 995 | AV4: =AP4*0.65 -> 1409.2 | AW4: =AQ4*0.65 -> 517.4 | AX4: Есть разбалансировка, один под жрет гораздо больше остальных ресурсов и обрабатывает гораздо больший трафик Был включен радиус-сервер, поэтому развить 200 RPS не получилось, только 75. Надо выключить и попробовать снова | AY4: https://10.116.41.195/grafana/d/edo-radius-full/edo-radius3a-full-auth-acct-2b-kafka-2b-infra?orgId=1&from=1761998400000&to=1761998879000 | AZ4: screencapture-10-116-41-195-grafana-d-edo-radius-full-edo-radius3a-full-auth-acct-2b-kafka-2b-infra-2025-11-01-17_48_58.pdf | BA4: Обновленный скрипт для предотвращения пересечений | BB4: TLS_VUS=700 TLS_MAXVUS=1200 TLS_AVG_ITER_SEC=1.5 TLS_TIMEUNIT=1s TLS_STAGES="1m@120,3m@200,1m@0" START_JITTER_SEC=2 SLEEP_JITTER_SEC=0.05 NAS_IP_MAX_INFLIGHT=30 NAS_LOCK_WAIT_MS=60000 EAPOL_TIMEOUT_SEC=60 EXEC_TIMEOUT_SEC=90 RADIUS_ADDRS="10.116.41.195" RADIUS_SECRET=cisco CSV_PATH=./users-10.csv CA_CERT=./ROOT_WIN-AD.cer TLS_PFX_DIR=./certs-eap-tls TLS_PFX_EXT=.pfx PRIVATE_KEY_PASS=12345 TLS_MAC_FILE=./macs.txt EAPOL_NAS_IP_LIST="10.116.42.70,10.116.42.71,10.116.42.72,10.116.42.73,10.116.42.74,10.116.42.75,10.116.42.76,10.116.42.77,10.116.42.78,10.116.42.79" RPS_SECOND_STATS=true RPS_FILE=./tls_rps_sec.log LOG_ALL_FAILURES=true ERROR_LOG=./tls_errors.log EAPOL_BIN=./eapol_test_2.11 k6-exec run radius_load_tls.js | BC4: 10 | BD4: 11 | BE4: 10000 | BF4: 3 | BG4: 16 | BH4: 64 | BI4: 120
A5: old_4 | B5: 2025-11-05T17:01:30.148Z | C5: EAP-TLS | D5: 1m@120,30m@250,1m@0 | G5: 250 | R5: 2500 | S5: 150 | T5: 3000 | U5: 300 | V5: 1200 | W5: 222524 | X5: 0 | Y5: 221320 | Z5: =Y5/(W5+X5) -> 0.99458935 | AA5: 1204 | AB5: =AA5/W5 -> 0.0054106523 | AC5: 3 | AD5: =AC5/W5 -> 1.3481692e-05 | AE5: 78 | AF5: =AE5/W5 -> 0.00035052399 | AG5: 1963 | AH5: 4469 | AI5: 62500 | AJ5: 7623.337 | AK5: 78423.128 | AL5: 6 | AM5: 367 | AN5: =AM5/AL5 -> 61.166667 | AO5: 2.376 | AP5: =AO5*1000 -> 2376 | AQ5: 1000 | AR5: 54.73 | AS5: 33.28 | AT5: =AP5*1.25 -> 2970 | AU5: =AQ5*1.25 -> 1250 | AV5: =AP5*0.65 -> 1544.4 | AW5: =AQ5*0.65 -> 650 | AX5: Система выдерживает нагрузку на 6 нодах, 3 отдельных таймаута | AY5: https://10.116.41.195/grafana/d/edo-radius-full/edo-radius3a-full-auth-acct-2b-kafka-2b-infra?orgId=1&from=1762360200000&to=1762362179000 | AZ5: screencapture-10-116-41-195-grafana-d-edo-radius-full-edo-radius3a-full-auth-acct-2b-kafka-2b-infra-2025-11-06-10_47_29.pdf | BA5: soak-script | BB5: TLS_VUS=700 TLS_MAXVUS=1200 TLS_AVG_ITER_SEC=1.5 TLS_TIMEUNIT=1s TLS_STAGES="1m@120,30m@250,1m@0" START_JITTER_SEC=2 SLEEP_JITTER_SEC=0.05 NAS_IP_MAX_INFLIGHT=30 NAS_LOCK_WAIT_MS=60000 EAPOL_TIMEOUT_SEC=60 EXEC_TIMEOUT_SEC=90 RADIUS_ADDRS="10.116.41.195" RADIUS_SECRET=cisco CSV_PATH=./users-10.csv CA_CERT=./ROOT_WIN-AD.cer TLS_PFX_DIR=./certs-eap-tls TLS_PFX_EXT=.pfx PRIVATE_KEY_PASS=12345 TLS_MAC_FILE=./macs.txt EAPOL_NAS_IP_LIST="10.116.42.70,10.116.42.71,10.116.42.72,10.116.42.73,10.116.42.74,10.116.42.75,10.116.42.76,10.116.42.77,10.116.42.78,10.116.42.79" RPS_SECOND_STATS=true RPS_FILE=./tls_rps_sec.log LOG_ALL_FAILURES=true ERROR_LOG=./tls_errors.log EAPOL_BIN=./eapol_test_2.11 K6_WEB_DASHBOARD=true k6-exec run radius_load_tls.js | BC5: 10 | BD5: 11 | BE5: 10000 | BF5: 3 | BG5: 16 | BH5: 64 | BI5: 120
A6: old_5 | B6: ='test-script'!B5 -> #REF! | C6: ='test-script'!C5 -> #REF! | D6: ='test-script'!D5 -> #REF! | E6: 45967.499 | F6: 45967.504 | G6: 250 | H6: 170623 | I6: 0.0182 | J6: 0.000942 | K6: 0.596 / 4.02 / 6.38 | L6: 709 | M6: 0 | N6: 0 | O6: 125 | P6: 148 | Q6: 224 | R6: 2500 | S6: 150 | T6: 3000 | U6: 300 | V6: 1200 | W6: 22134 | X6: 0 | Y6: 21424 | Z6: =Y6/(W6+X6) -> 0.96792265 | AA6: 710 | AB6: =AA6/W6 -> 0.032077347 | AC6: 0 | AD6: =AC6/W6 -> 0 | AE6: 0 | AF6: =AE6/W6 -> 0 | AG6: 2616000 | AH6: 6020000 | AI6: 19496000 | AJ6: 8468659 | AK6: 57014718 | AL6: 6 | AM6: 238 | AN6: =AM6/AL6 -> 39.666667 | AO6: 1.8 | AP6: =AO6*1000 -> 1800 | AQ6: 1117 | AT6: =AP6*1.25 -> 2250 | AU6: =AQ6*1.25 -> 1396.25 | AV6: =AP6*0.65 -> 1170 | AW6: =AQ6*0.65 -> 726.05 | AY6: https://10.116.41.195/grafana/d/edo-radius-full/edo-radius3a-full-auth-acct-2b-kafka-2b-infra?orgId=1&from=1762419540000&to=1762419959000 | BB6: TLS_VUS="700" TLS_MAXVUS="1200" TLS_AVG_ITER_SEC="1.5" TLS_TIMEUNIT="1s" TLS_STAGES="30s@120,30s@250,45s@400,30s@250,30s@0" START_JITTER_SEC="2" SLEEP_JITTER_SEC="0.05" RADIUS_ADDRS="10.116.41.195" RADIUS_SECRET="cisco" EAPOL_NAS_IP_LIST="10.116.42.70,10.116.42.71,10.116.42.72,10.116.42.73,10.116.42.74,10.116.42.75,10.116.42.76,10.116.42.77,10.116.42.78,10.116.42.79" NAS_IP_MAX_INFLIGHT="30" NAS_LOCK_WAIT_MS="60000" CA_CERT="./ROOT_WIN-AD.cer" TLS_PFX_DIR="./certs-eap-tls" TLS_PFX_EXT=".pfx" PRIVATE_KEY_PASS="12345" TLS_MAC_FILE="./macs.txt" CSV_PATH="./users-10.csv" RPS_FILE="./tls_rps_sec.log" ERROR_LOG="./tls_errors.log" EAPOL_BIN="./eapol_test_2.11" EAPOL_TIMEOUT_SEC="60" EXEC_TIMEOUT_SEC="90" RPS_SECOND_STATS="true" LOG_ALL_FAILURES="true" k6-exec run radius_load_tls.js | BC6: 10 | BD6: 11 | BE6: 10000 | BF6: 3 | BG6: 8 | BH6: 24 | BI6: 120
A7: old_6 | B7: 2025-11-07 10:38:08 | C7: EAP-TLS | D7: 30s@120,30s@250,45s@400,30s@250,30s@0 | E7: 2025-11-07 10:35:20 | F7: 2025-11-07 10:38:08 | G7: 400 | H7: 111667.96 | I7: 0.188679 | J7: 2.9477 | K7: 2.2362 | L7: 51.8 | M7: 0 | N7: 0 | O7: 144.95 | P7: 148.4602 | Q7: 84.997 | R7: 2500 | S7: 150 | T7: 3000 | U7: 300 | V7: 1200 | W7: 14864 | X7: 0 | Y7: 14864 | Z7: =Y7/(W7+X7) -> 1 | AA7: 0 | AB7: =AA7/W7 -> 0 | AC7: 0 | AD7: =AC7/W7 -> 0 | AE7: 0 | AF7: =AE7/W7 -> 0 | AG7: 1791.5154 | AH7: 4162.85 | AI7: 10238 | AJ7: 8664.4719 | AK7: 51557.798 | AL7: 6 | AM7: 230 | AN7: =AM7/AL7 -> 38.333333 | AO7: 2.1339 | AP7: 2149.3897 | AQ7: 1004.957 | AR7: 82.8875 | AS7: 84.5894 | AT7: 2687 | AU7: 1256 | AV7: 1397 | AW7: 653 | AY7: https://10.116.41.195/grafana/d/edo-radius-full/edo-radius3a-full-auth-acct-2b-kafka-2b-infra?orgId=1&from=1762500920000&to=1762501199000&var-DS_PROMETHEUS=prometheus&var-namespace=edo&var-job=All&var-pod=All&var-node=All&var-kafka_topic=All&var-kafka_group=All&var-status=accepts | BA7: peak_script_morning | BB7: TLS_VUS="700" TLS_MAXVUS="1200" TLS_AVG_ITER_SEC="1.5" TLS_TIMEUNIT="1s" TLS_STAGES="30s@120,30s@250,45s@400,30s@250,30s@0" START_JITTER_SEC="2" SLEEP_JITTER_SEC="0.05" RADIUS_ADDRS="10.116.41.195" RADIUS_SECRET="cisco" EAPOL_NAS_IP_LIST="10.116.42.70,10.116.42.71,10.116.42.72,10.116.42.73,10.116.42.74,10.116.42.75,10.116.42.76,10.116.42.77,10.116.42.78,10.116.42.79" NAS_IP_MAX_INFLIGHT="30" NAS_LOCK_WAIT_MS="60000" CA_CERT="./ROOT_WIN-AD.cer" TLS_PFX_DIR="./certs-eap-tls" TLS_PFX_EXT=".pfx" PRIVATE_KEY_PASS="12345" TLS_MAC_FILE="./macs.txt" CSV_PATH="./users-10.csv" RPS_FILE="./tls_rps_sec.log" ERROR_LOG="./tls_errors.log" EAPOL_BIN="./eapol_test_2.11" EAPOL_TIMEOUT_SEC="60" EXEC_TIMEOUT_SEC="90" RPS_SECOND_STATS="true" LOG_ALL_FAILURES="true" k6-exec run radius_load_tls.js | BC7: 10 | BD7: 10 | BE7: 10000 | BF7: 3 | BG7: 8 | BH7: 24 | BI7: 120
A8: old_7 | B8: 2025-11-07 12:29:37 | C8: EAP-TLS | D8: 1m@120,30m@250,1m@0 | E8: 2025-11-07 11:57:01 | F8: 2025-11-07 12:29:37 | G8: 250 | H8: 629807.79 | I8: 0.128417 | J8: 3.5398 | K8: 4.2375 | L8: 389 | M8: 0 | N8: 0 | O8: 155.7862 | P8: 159.4236 | Q8: 73.237 | R8: 2500 | S8: 150 | T8: 3000 | U8: 300 | V8: 6000 | W8: 85991 | X8: 796 | Y8: 72926 | Z8: =Y8/(W8+X8) -> 0.84028714 | AA8: 13861 | AB8: =AA8/W8 -> 0.16119129 | AC8: 8 | AD8: =AC8/W8 -> 9.3032992e-05 | AE8: 0 | AF8: =AE8/W8 -> 0 | AG8: 14399.675 | AH8: 39549.5 | AI8: 127115 | AJ8: 104439.76 | AK8: 289612.88 | AL8: 6 | AM8: 1016 | AN8: 169.33 | AO8: 2.0429 | AP8: 2177.008 | AQ8: 1027.9023 | AR8: 75.6167 | AS8: 80.9244 | AT8: 2721 | AU8: 1285 | AV8: 1415 | AW8: 668 | AY8: https://10.116.41.195/grafana/d/edo-radius-full/edo-radius3a-full-auth-acct-2b-kafka-2b-infra?orgId=1&from=1762505820000&to=1762507919000 | BB8: TLS_VUS="700" TLS_MAXVUS="6000" TLS_AVG_ITER_SEC="1.5" TLS_TIMEUNIT="1s" TLS_STAGES="1m@120,30m@250,1m@0" START_JITTER_SEC="2" SLEEP_JITTER_SEC="0.05" RADIUS_ADDRS="10.116.41.195" RADIUS_SECRET="cisco" EAPOL_NAS_IP_LIST="10.116.42.70,10.116.42.71,10.116.42.72,10.116.42.73,10.116.42.74,10.116.42.75,10.116.42.76,10.116.42.77,10.116.42.78,10.116.42.79" NAS_IP_MAX_INFLIGHT="30" NAS_LOCK_WAIT_MS="60000" CA_CERT="./ROOT_WIN-AD.cer" TLS_PFX_DIR="./certs-eap-tls" TLS_PFX_EXT=".pfx" PRIVATE_KEY_PASS="12345" TLS_MAC_FILE="./macs.txt" CSV_PATH="./users-10.csv" RPS_FILE="./tls_rps_sec.log" ERROR_LOG="./tls_errors.log" EAPOL_BIN="./eapol_test_2.11" EAPOL_TIMEOUT_SEC="60" EXEC_TIMEOUT_SEC="90" RPS_SECOND_STATS="true" LOG_ALL_FAILURES="true" K6_WEB_DASHBOARD="true" k6-exec run radius_load_tls.js | BC8: 10 | BD8: 10 | BE8: 10000 | BF8: 3 | BG8: 8 | BH8: 24 | BI8: 120
A9: old_8 | B9: 2025-11-07 13:28:53 | C9: EAP-TLS | D9: 1m@300,1m@0,1m@300,1m@0,1m@300,2m@0 | E9: 2025-11-07 13:21:23 | F9: 2025-11-07 13:28:53 | G9: 300 | H9: 105008.25 | I9: 0.013593 | J9: 0.1891 | K9: 1.26 | L9: 52 | M9: 0 | N9: 0 | O9: 65.94 | P9: 68.93 | Q9: 77.3067 | R9: 2500 | S9: 150 | T9: 3000 | U9: 300 | V9: 3000 | W9: 12861 | X9: 723 | Y9: 12876 | Z9: =Y9/(W9+X9) -> 0.94787986 | AA9: 1 | AB9: =AA9/W9 -> 7.7754451e-05 | AC9: 0 | AD9: =AC9/W9 -> 0 | AE9: 0 | AF9: =AE9/W9 -> 0 | AG9: 4596.0297 | AH9: 13141.2 | AI9: 52985 | AJ9: 74535.47 | AK9: 143907.6 | AL9: 6 | AM9: 222 | AN9: =AM9/6 -> 37 | AO9: 1.4696 | AP9: 1392.9207 | AQ9: 864.7773 | AR9: 60.625 | AS9: 79.7271 | AT9: 1741 | AU9: 1081 | AV9: 905 | AW9: 562 | AX9: 12852 complete and 723 interrupted iterations | AY9: https://10.116.41.195/grafana/d/edo-radius-full/edo-radius3a-full-auth-acct-2b-kafka-2b-infra?orgId=1&from=1762510860000&to=1762511460000 | BA9: профиль 300/0/300/0 показывает хорошие результаты | BB9: TLS_VUS="700" TLS_MAXVUS="3000" TLS_AVG_ITER_SEC="1.5" TLS_TIMEUNIT="1s" TLS_STAGES="1m@300,1m@0,1m@300,1m@0,1m@300,2m@0" START_JITTER_SEC="2" SLEEP_JITTER_SEC="0.05" RADIUS_ADDRS="10.116.41.195" RADIUS_SECRET="cisco" EAPOL_NAS_IP_LIST="10.116.42.70,10.116.42.71,10.116.42.72,10.116.42.73,10.116.42.74,10.116.42.75,10.116.42.76,10.116.42.77,10.116.42.78,10.116.42.79" NAS_IP_MAX_INFLIGHT="30" NAS_LOCK_WAIT_MS="60000" CA_CERT="./ROOT_WIN-AD.cer" TLS_PFX_DIR="./certs-eap-tls" TLS_PFX_EXT=".pfx" PRIVATE_KEY_PASS="12345" TLS_MAC_FILE="./macs.txt" CSV_PATH="./users-10.csv" RPS_FILE="./tls_rps_sec.log" ERROR_LOG="./tls_errors.log" EAPOL_BIN="./eapol_test_2.11" EAPOL_TIMEOUT_SEC="60" EXEC_TIMEOUT_SEC="90" RPS_SECOND_STATS="true" LOG_ALL_FAILURES="true" k6-exec run radius_load_tls.js | BC9: 10 | BD9: 10 | BE9: 10000 | BF9: 3 | BG9: 8 | BH9: 24 | BI9: 120
A10: old_9 | B10: 2025-11-07 13:54:22 | C10: EAP-TLS | D10: 45s@150,45s@220,45s@280,45s@320,45s@360,45s@400,45s@0 | E10: 2025-11-07 13:48:33 | F10: 2025-11-07 13:54:22 | G10: 400 | H10: 79739.176 | I10: 0.02525 | J10: 0.212 | K10: 1.635 | L10: 110 | M10: 0 | N10: 0 | O10: 64.23 | P10: 68.595 | Q10: 39.712 | R10: 2500 | S10: 150 | T10: 3000 | U10: 300 | V10: 4126 | W10: 9283 | X10: 1985 | Y10: 9166 | Z10: =Y10/(W10+X10) -> 0.81345403 | AA10: 154 | AB10: =AA10/W10 -> 0.016589465 | AC10: 0 | AD10: =AC10/W10 -> 0 | AE10: 0 | AF10: =AE10/W10 -> 0 | AG10: 6595.3348 | AH10: 17407.1 | AI10: 32907 | AJ10: 77876.262 | AK10: 125163.51 | AL10: 6 | AM10: 211 | AN10: =AM10/AL10 -> 35.166667 | AO10: 1.2688 | AP10: 1509.2145 | AQ10: 874.25 | AR10: 60.2958 | AS10: 80.0966 | AT10: 1887 | AU10: 1093 | AV10: 981 | AW10: 568 | AY10: https://10.116.41.195/grafana/d/edo-radius-full/edo-radius3a-full-auth-acct-2b-kafka-2b-infra?orgId=1&from=1762512513000&to=1762512959000 | BB10: TLS_VUS="700" TLS_MAXVUS="6000" TLS_AVG_ITER_SEC="1.5" TLS_TIMEUNIT="1s" TLS_STAGES="45s@150,45s@220,45s@280,45s@320,45s@360,45s@400,45s@0" START_JITTER_SEC="2" SLEEP_JITTER_SEC="0.05" RADIUS_ADDRS="10.116.41.195" RADIUS_SECRET="cisco" EAPOL_NAS_IP_LIST="10.116.42.70,10.116.42.71,10.116.42.72,10.116.42.73,10.116.42.74,10.116.42.75,10.116.42.76,10.116.42.77,10.116.42.78,10.116.42.79" NAS_IP_MAX_INFLIGHT="30" NAS_LOCK_WAIT_MS="60000" CA_CERT="./ROOT_WIN-AD.cer" TLS_PFX_DIR="./certs-eap-tls" TLS_PFX_EXT=".pfx" PRIVATE_KEY_PASS="12345" TLS_MAC_FILE="./macs.txt" CSV_PATH="./users-10.csv" RPS_FILE="./tls_rps_sec.log" ERROR_LOG="./tls_errors.log" EAPOL_BIN="./eapol_test_2.11" EAPOL_TIMEOUT_SEC="60" EXEC_TIMEOUT_SEC="90" RPS_SECOND_STATS="true" LOG_ALL_FAILURES="true" k6-exec run radius_load_tls.js | BC10: 10 | BD10: 10 | BE10: 10000 | BF10: 3 | BG10: 8 | BH10: 24 | BI10: 120
A11: old_10 | B11: 2025-11-07 17:12:22 | C11: EAP-TLS | D11: 30s@80,30s@160,2m@250,30s@160,30s@0 | E11: 2025-11-07 16:07:52 | F11: 2025-11-07 16:12:22 | G11: 250 | H11: 31930.737 | I11: 0.1846 | J11: 0.0154 | K11: 0.8313 | L11: 25.8 | M11: 0 | N11: 0 | O11: 28.69 | P11: 30.13 | Q11: 223.6068 | R11: 2500 | S11: 150 | T11: 3000 | U11: 300 | V11: 1200 | W11: 3874 | X11: 643 | Y11: 3878 | Z11: =Y11/(W11+X11) -> 0.85853443 | AA11: 0 | AB11: =AA11/W11 -> 0 | AC11: 0 | AD11: =AC11/W11 -> 0 | AE11: 0 | AF11: =AE11/W11 -> 0 | AG11: 1575.5281 | AH11: 3806.9 | AI11: 6622 | AJ11: 64129.684 | AK11: 73590.284 | AL11: 6 | AM11: 85 | AN11: 14.17 | AO11: 1.026 | AP11: 1026.0248 | AQ11: 764.5117 | AR11: 44 | AS11: 76.7 | AT11: 1283 | AU11: 956 | AV11: 667 | AW11: 497 | AY11: https://10.116.41.195/grafana/d/edo-radius-full/edo-radius3a-full-auth-acct-2b-kafka-2b-infra?orgId=1&from=1762520872000&to=1762521142000 | BB11: TLS_VUS="700" TLS_MAXVUS="6000" TLS_AVG_ITER_SEC="1.5" TLS_TIMEUNIT="1s" TLS_STAGES="45s@150,45s@220,45s@280,45s@320,45s@360,45s@400,45s@0" START_JITTER_SEC="2" SLEEP_JITTER_SEC="0.05" RADIUS_ADDRS="10.116.41.195" RADIUS_SECRET="cisco" EAPOL_NAS_IP_LIST="10.116.42.70,10.116.42.71,10.116.42.72,10.116.42.73,10.116.42.74,10.116.42.75,10.116.42.76,10.116.42.77,10.116.42.78,10.116.42.79" NAS_IP_MAX_INFLIGHT="30" NAS_LOCK_WAIT_MS="60000" CA_CERT="./ROOT_WIN-AD.cer" TLS_PFX_DIR="./certs-eap-tls" TLS_PFX_EXT=".pfx" PRIVATE_KEY_PASS="12345" TLS_MAC_FILE="./macs.txt" CSV_PATH="./users-10.csv" RPS_FILE="./tls_rps_sec.log" ERROR_LOG="./tls_errors.log" EAPOL_BIN="./eapol_test_2.11" EAPOL_TIMEOUT_SEC="60" EXEC_TIMEOUT_SEC="90" RPS_SECOND_STATS="true" LOG_ALL_FAILURES="true" k6-exec run radius_load_tls.js | BC11: 10 | BD11: 10 | BE11: 10000 | BF11: 3 | BG11: 8 | BH11: 16 | BI11: 120
A12: old_11 | B12: 2025-11-07 15:40:57 | C12: EAP-TLS | D12: 45s@150,45s@220,45s@280,45s@320,45s@360,45s@400,45s@0 | E12: 2025-11-07 15:35:08 | F12: 2025-11-07 15:40:57 | G12: 400 | H12: 79717.046 | I12: 0.01975 | J12: 0.1788 | K12: 1.3162 | L12: 362 | M12: 0 | N12: 0 | O12: 67.08 | P12: 67.6563 | Q12: 43.1875 | R12: 2500 | S12: 150 | T12: 3000 | U12: 300 | V12: 4269 | W12: 9177 | X12: 2366 | Y12: 9332 | Z12: =Y12/(W12+X12) -> 0.80845534 | AA12: 32 | AB12: =AA12/W12 -> 0.0034869783 | AC12: 0 | AD12: =AC12/W12 -> 0 | AE12: 0 | AF12: =AE12/W12 -> 0 | AG12: 6480.8576 | AH12: 19541 | AI12: 48575 | AJ12: 78840.184 | AK12: 149215.57 | AL12: 6 | AM12: 263 | AN12: =AM12/AL12 -> 43.833333 | AO12: 1.4149 | AP12: 1414.9191 | AQ12: 770.4375 | AR12: 66.6675 | AS12: 75.3967 | AT12: 1769 | AU12: 963 | AV12: 920 | AW12: 501 | AY12: https://10.116.41.195/grafana/d/edo-radius-full/edo-radius3a-full-auth-acct-2b-kafka-2b-infra?orgId=1&from=1762518900000&to=1762519260000 | BB12: TLS_VUS="700" TLS_MAXVUS="6000" TLS_AVG_ITER_SEC="1.5" TLS_TIMEUNIT="1s" TLS_STAGES="45s@150,45s@220,45s@280,45s@320,45s@360,45s@400,45s@0" START_JITTER_SEC="2" SLEEP_JITTER_SEC="0.05" RADIUS_ADDRS="10.116.41.195" RADIUS_SECRET="cisco" EAPOL_NAS_IP_LIST="10.116.42.70,10.116.42.71,10.116.42.72,10.116.42.73,10.116.42.74,10.116.42.75,10.116.42.76,10.116.42.77,10.116.42.78,10.116.42.79" NAS_IP_MAX_INFLIGHT="30" NAS_LOCK_WAIT_MS="60000" CA_CERT="./ROOT_WIN-AD.cer" TLS_PFX_DIR="./certs-eap-tls" TLS_PFX_EXT=".pfx" PRIVATE_KEY_PASS="12345" TLS_MAC_FILE="./macs.txt" CSV_PATH="./users-10.csv" RPS_FILE="./tls_rps_sec.log" ERROR_LOG="./tls_errors.log" EAPOL_BIN="./eapol_test_2.11" EAPOL_TIMEOUT_SEC="60" EXEC_TIMEOUT_SEC="90" RPS_SECOND_STATS="true" LOG_ALL_FAILURES="true" k6-exec run radius_load_tls.js | BC12: 10 | BD12: 10 | BE12: 10000 | BF12: 3 | BG12: 8 | BH12: 16 | BI12: 120
A13: old_12 | B13: 2025-11-07 16:44:54 | C13: EAP-TLS | D13: 30s@120,30s@250,45s@400,30s@250,30s@0 | E13: 2025-11-07 16:41:38 | F13: 2025-11-07 16:44:54 | G13: 400 | H13: 30301.478 | I13: 0.567 | J13: 0.0542 | K13: 0.7188 | L13: 0 | M13: 0 | N13: 0 | O13: 49.5085 | P13: 51.38 | Q13: 40.9702 | R13: 2500 | S13: 150 | T13: 3000 | U13: 300 | V13: 2708 | W13: 3497 | X13: 1413 | Y13: 3518 | Z13: =Y13/(W13+X13) -> 0.71649695 | AA13: 0 | AB13: =AA13/W13 -> 0 | AC13: 0 | AD13: =AC13/W13 -> 0 | AE13: 0 | AF13: =AE13/W13 -> 0 | AG13: 3757.4716 | AH13: 9612.05 | AI13: 41836 | AJ13: 70725.993 | AK13: 110285.4 | AL13: 6 | AM13: 125 | AN13: 20.83 | AO13: 1.1962 | AP13: 1103.3033 | AQ13: 766.6406 | AR13: 50.8 | AS13: 78.3 | AT13: 1379 | AU13: 958 | AV13: 717 | AW13: 498 | AY13: https://10.116.41.195/grafana/d/edo-radius-full/edo-radius3a-full-auth-acct-2b-kafka-2b-infra?orgId=1&from=1762522898000&to=1762523159000 | BB13: TLS_VUS="700" TLS_MAXVUS="6000" TLS_AVG_ITER_SEC="1.5" TLS_TIMEUNIT="1s" TLS_STAGES="30s@120,30s@250,45s@400,30s@250,30s@0" START_JITTER_SEC="2" SLEEP_JITTER_SEC="0.05" RADIUS_ADDRS="10.116.41.195" RADIUS_SECRET="cisco" EAPOL_NAS_IP_LIST="10.116.42.70,10.116.42.71,10.116.42.72,10.116.42.73,10.116.42.74,10.116.42.75,10.116.42.76,10.116.42.77,10.116.42.78,10.116.42.79" NAS_IP_MAX_INFLIGHT="30" NAS_LOCK_WAIT_MS="60000" CA_CERT="./ROOT_WIN-AD.cer" TLS_PFX_DIR="./certs-eap-tls" TLS_PFX_EXT=".pfx" PRIVATE_KEY_PASS="12345" TLS_MAC_FILE="./macs.txt" CSV_PATH="./users-10.csv" RPS_FILE="./tls_rps_sec.log" ERROR_LOG="./tls_errors.log" EAPOL_BIN="./eapol_test_2.11" EAPOL_TIMEOUT_SEC="60" EXEC_TIMEOUT_SEC="90" RPS_SECOND_STATS="true" LOG_ALL_FAILURES="true" k6-exec run radius_load_tls.js | BC13: 10 | BD13: 10 | BE13: 10000 | BF13: 3 | BG13: 8 | BH13: 16 | BI13: 120
A14: old_13 | B14: 2025-11-07 18:14:57 | C14: EAP-TLS | D14: 1m@120,20m@250,1m@0 | E14: 2025-11-07 17:52:21 | F14: 2025-11-07 18:14:57 | G14: 250 | H14: 436624.4 | I14: 0.051953 | J14: 0.8333 | K14: 3.46 | L14: 297.6484 | M14: 0 | N14: 0 | O14: 84.85 | P14: 88.525 | Q14: 223.6068 | R14: 2500 | S14: 150 | T14: 3000 | U14: 300 | V14: 6000 | W14: 55339 | X14: 3672 | Y14: 51679 | Z14: =Y14/(W14+X14) -> 0.87575198 | AA14: 5078 | AB14: =AA14/W14 -> 0.091761687 | AC14: 3 | AD14: =AC14/W14 -> 5.4211316e-05 | AE14: 0 | AF14: =AE14/W14 -> 0 | AG14: 13982.987 | AH14: 39284.6 | AI14: 93976 | AJ14: 103457.93 | AK14: 287817.95 | AL14: 6 | AM14: 432 | AN14: 72 | AO14: 1.6167 | AP14: 1616.7239 | AQ14: 924.7656 | AR14: 62.2 | AS14: 83 | AT14: 2021 | AU14: 1156 | AV14: 1051 | AW14: 601 | AY14: https://10.116.41.195/grafana/d/edo-radius-full/edo-radius3a-full-auth-acct-2b-kafka-2b-infra?orgId=1&from=1762527141000&to=1762528499000 | BB14: TLS_VUS="700" TLS_MAXVUS="6000" TLS_AVG_ITER_SEC="1.5" TLS_TIMEUNIT="1s" TLS_STAGES="1m@120,20m@250,1m@0" START_JITTER_SEC="2" SLEEP_JITTER_SEC="0.05" RADIUS_ADDRS="10.116.41.195" RADIUS_SECRET="cisco" EAPOL_NAS_IP_LIST="10.116.42.70,10.116.42.71,10.116.42.72,10.116.42.73,10.116.42.74,10.116.42.75,10.116.42.76,10.116.42.77,10.116.42.78,10.116.42.79" NAS_IP_MAX_INFLIGHT="30" NAS_LOCK_WAIT_MS="60000" CA_CERT="./ROOT_WIN-AD.cer" TLS_PFX_DIR="./certs-eap-tls" TLS_PFX_EXT=".pfx" PRIVATE_KEY_PASS="12345" TLS_MAC_FILE="./macs.txt" CSV_PATH="./users-10.csv" RPS_FILE="./tls_rps_sec.log" ERROR_LOG="./tls_errors.log" EAPOL_BIN="./eapol_test_2.11" EAPOL_TIMEOUT_SEC="60" EXEC_TIMEOUT_SEC="90" RPS_SECOND_STATS="true" LOG_ALL_FAILURES="true" k6-exec run radius_load_tls.js | BC14: 10 | BD14: 10 | BE14: 10000 | BF14: 3 | BG14: 8 | BH14: 16 | BI14: 120
A15: old_14 | B15: 2025-11-07 21:31:08 | C15: EAP-TLS | D15: 1m@120,20m@250,1m@0 | E15: 2025-11-07 21:08:37 | F15: 2025-11-07 21:31:08 | G15: 250 | H15: 404741.1 | I15: 0.032237 | J15: 0.7693 | K15: 2.5825 | L15: 346.3242 | M15: 0 | N15: 0 | O15: 73.84 | P15: 82.6679 | Q15: 59.0432 | R15: 2500 | S15: 150 | T15: 3000 | U15: 300 | V15: 6000 | W15: 53302 | X15: 2047 | Y15: 48441 | Z15: =Y15/(W15+X15) -> 0.87519196 | AA15: 5707 | AB15: =AA15/W15 -> 0.10706915 | AC15: 2419 | AD15: =AC15/W15 -> 0.045382912 | AE15: 0 | AF15: =AE15/W15 -> 0 | AG15: 17218.332 | AH15: 65304.65 | AI15: 118926 | AJ15: 106873.24 | AK15: 288756.33 | AL15: 6 | AM15: 1050 | AN15: 175 | AO15: 1.6844 | AP15: 1701.7943 | AQ15: 941.9688 | AR15: 57.8 | AS15: 68.1 | AT15: 2127 | AU15: 1177 | AV15: 1106 | AW15: 612 | AY15: https://10.116.41.195/grafana/d/edo-radius-full/edo-radius3a-full-auth-acct-2b-kafka-2b-infra?orgId=1&from=1762539021000&to=1762540319000 | BB15: TLS_VUS="700" TLS_MAXVUS="6000" TLS_AVG_ITER_SEC="1.5" TLS_TIMEUNIT="1s" TLS_STAGES="1m@120,20m@250,1m@0" START_JITTER_SEC="2" SLEEP_JITTER_SEC="0.05" RADIUS_ADDRS="10.116.41.195" RADIUS_SECRET="cisco" EAPOL_NAS_IP_LIST="10.116.42.70,10.116.42.71,10.116.42.72,10.116.42.73,10.116.42.74,10.116.42.75,10.116.42.76,10.116.42.77,10.116.42.78,10.116.42.79" NAS_IP_MAX_INFLIGHT="30" NAS_LOCK_WAIT_MS="60000" CA_CERT="./ROOT_WIN-AD.cer" TLS_PFX_DIR="./certs-eap-tls" TLS_PFX_EXT=".pfx" PRIVATE_KEY_PASS="12345" TLS_MAC_FILE="./macs.txt" CSV_PATH="./users-10.csv" RPS_FILE="./tls_rps_sec.log" ERROR_LOG="./tls_errors.log" EAPOL_BIN="./eapol_test_2.11" EAPOL_TIMEOUT_SEC="60" EXEC_TIMEOUT_SEC="90" RPS_SECOND_STATS="true" LOG_ALL_FAILURES="true" k6-exec run radius_load_tls.js | BC15: 10 | BD15: 10 | BE15: 10000 | BF15: 3 | BG15: 8 | BH15: 20 | BI15: 120
A16: old_15 | B16: 2025-11-07 22:14:35 | C16: EAP-TLS | D16: 45s@150,45s@220,45s@280,45s@320,45s@360,45s@400,45s@0 | E16: 2025-11-07 22:08:49 | F16: 2025-11-07 22:14:35 | G16: 400 | H16: 81219.05 | I16: 0.016456 | J16: 0.2747 | K16: 1.8537 | L16: 41.1602 | M16: 0 | N16: 0 | O16: 67.84 | P16: 71.22 | Q16: 81.6497 | R16: 2500 | S16: 150 | T16: 3000 | U16: 300 | V16: 4098 | W16: 9587 | X16: 1728 | Y16: 9699 | Z16: =Y16/(W16+X16) -> 0.85718073 | AA16: 1 | AB16: =AA16/W16 -> 0.00010430792 | AC16: 0 | AD16: =AC16/W16 -> 0 | AE16: 0 | AF16: 0 | AG16: 6978.4142 | AH16: 16854.5 | AI16: 42443 | AJ16: 77776.217 | AK16: 142836.39 | AL16: 6 | AM16: 262 | AN16: 43.67 | AO16: 1.5335 | AP16: 1533.5145 | AQ16: 920.3555 | AT16: 1917 | AU16: 1150 | AV16: 997 | AW16: 598 | AX16: 8958 complete and 2152 interrupted iterations - очень длинные итерации, не успели закончиться. Скорее всего, не успевают обработаться | AY16: https://10.116.41.195/grafana/d/edo-radius-full/edo-radius3a-full-auth-acct-2b-kafka-2b-infra?orgId=1&from=1762542529000&to=1762542995000 | BB16: TLS_VUS="700" TLS_MAXVUS="6000" TLS_AVG_ITER_SEC="1.5" TLS_TIMEUNIT="1s" TLS_STAGES="45s@150,45s@220,45s@280,45s@320,45s@360,45s@400,45s@0" START_JITTER_SEC="2" SLEEP_JITTER_SEC="0.05" RADIUS_ADDRS="10.116.41.195" RADIUS_SECRET="cisco" EAPOL_NAS_IP_LIST="10.116.42.70,10.116.42.71,10.116.42.72,10.116.42.73,10.116.42.74,10.116.42.75,10.116.42.76,10.116.42.77,10.116.42.78,10.116.42.79" NAS_IP_MAX_INFLIGHT="30" NAS_LOCK_WAIT_MS="60000" CA_CERT="./ROOT_WIN-AD.cer" TLS_PFX_DIR="./certs-eap-tls" TLS_PFX_EXT=".pfx" PRIVATE_KEY_PASS="12345" TLS_MAC_FILE="./macs.txt" CSV_PATH="./users-10.csv" RPS_FILE="./tls_rps_sec.log" ERROR_LOG="./tls_errors.log" EAPOL_BIN="./eapol_test_2.11" EAPOL_TIMEOUT_SEC="60" EXEC_TIMEOUT_SEC="90" RPS_SECOND_STATS="true" LOG_ALL_FAILURES="true" k6-exec run radius_load_tls.js | BC16: 10 | BD16: 10 | BE16: 10000 | BF16: 3 | BG16: 8 | BH16: 20 | BI16: 120
A17: old_16 | B17: 2025-11-07 23:34:25 | C17: EAP-TLS | D17: 60s@150,120s@250,180s@400,180s@250,120s@150 | E17: 2025-11-07 23:22:51 | F17: 2025-11-07 23:34:25 | G17: 400 | H17: 409888.61 | I17: 0.088485 | J17: 0.026888 | K17: 3.4012 | L17: 117.5156 | M17: 0 | N17: 0 | O17: 141.62 | P17: 148.7666 | Q17: 141.4214 | R17: 2500 | S17: 150 | T17: 3000 | U17: 300 | V17: 4680 | W17: 50038 | X17: 1794 | Y17: 50194 | Z17: =Y17/(W17+X17) -> 0.9683979 | AA17: 114 | AB17: =AA17/W17 -> 0.0022782685 | AC17: 0 | AD17: =AC17/W17 -> 0 | AE17: 0 | AF17: 0 | AG17: 5608.1037 | AH17: 18330.65 | AI17: 62084 | AJ17: 31836.023 | AK17: 174055.76 | AL17: 6 | AM17: 363 | AN17: 60.5 | AO17: 2.168 | AP17: 2168.0407 | AQ17: 991.3828 | AR17: 64.7 | AS17: 70.7 | AT17: 2710 | AU17: 1239 | AV17: 1409 | AW17: 644 | AX17: 50038 complete and 1794 interrupted iterations | AY17: https://10.116.41.195/grafana/d/edo-radius-full/edo-radius3a-full-auth-acct-2b-kafka-2b-infra?orgId=1&from=1762546971921&to=1762547665044 | BB17: TLS_VUS="700" TLS_MAXVUS="6000" TLS_AVG_ITER_SEC="1.5" TLS_TIMEUNIT="1s" TLS_STAGES="60s@150,120s@250,180s@400,180s@250,120s@150" START_JITTER_SEC="2" SLEEP_JITTER_SEC="0.05" RADIUS_ADDRS="10.116.41.195" RADIUS_SECRET="cisco" EAPOL_NAS_IP_LIST="10.116.42.70,10.116.42.71,10.116.42.72,10.116.42.73,10.116.42.74,10.116.42.75,10.116.42.76,10.116.42.77,10.116.42.78,10.116.42.79" NAS_IP_MAX_INFLIGHT="120" NAS_LOCK_WAIT_MS="60000" CA_CERT="./ROOT_WIN-AD.cer" TLS_PFX_DIR="./certs-eap-tls" TLS_PFX_EXT=".pfx" PRIVATE_KEY_PASS="12345" TLS_MAC_FILE="./macs.txt" CSV_PATH="./users-10.csv" RPS_FILE="./tls_rps_sec.log" ERROR_LOG="./tls_errors.log" EAPOL_BIN="./eapol_test_2.11" EAPOL_TIMEOUT_SEC="75" EXEC_TIMEOUT_SEC="150" RPS_SECOND_STATS="true" LOG_ALL_FAILURES="true" K6_WEB_DASHBOARD="true" k6-exec run radius_load_tls.js | BC17: 10 | BD17: 10 | BE17: 10000 | BF17: 3 | BG17: 8 | BH17: 20 | BI17: 120
A18: 5 | B18: 2025-11-10 16:59:41 | C18: EAP-TLS | D18: 60s@40,60s@70,60s@100,60s@130,60s@0 | E18: 2025-11-10 16:54:09 | F18: 2025-11-10 16:59:41 | G18: 130 | H18: 49368.901 | I18: 0.5382 | J18: 0.0493 | K18: 0.9175 | L18: 31.2266 | M18: 0 | N18: 0 | O18: 46.1 | P18: 54.61 | Q18: 101.0153 | R18: 2500 | S18: 150 | T18: 3000 | U18: 300 | V18: 2403 | W18: =Y18+X18 -> 19664 | X18: 13653 | Y18: 6011 | Z18: =Y18/W18 -> 0.30568552 | AA18: 0 | AB18: =AA18/W18 -> 0 | AC18: 0 | AD18: =AC18/W18 -> 0 | AE18: 0 | AF18: 0 | AG18: 2981.3365 | AH18: 8311.5 | AI18: 36608 | AJ18: 68614.112 | AK18: 111092.19 | AL18: 6 | AM18: 181 | AN18: 30.17 | AO18: 1.2945 | AP18: =AO18*1000 -> 1294.5 | AQ18: 706.2188 | AR18: 48.6 | AS18: 72.5 | AT18: 1990 | AU18: 883 | AV18: 1035 | AW18: 459 | AX18: много дропов, длина итерации больше минуты | AY18: https://10.116.41.195/grafana/d/edo-radius-full/edo-radius3a-full-auth-acct-2b-kafka-2b-infra?orgId=1&from=1762782849507&to=1762783181222 | BB18: TLS_VUS="700" TLS_MAXVUS="4000" TLS_AVG_ITER_SEC="1.5" TLS_TIMEUNIT="1s" TLS_STAGES="60s@40,60s@70,60s@100,60s@130,60s@0" START_JITTER_SEC="2" SLEEP_JITTER_SEC="0.05" RADIUS_ADDRS="10.116.41.195" RADIUS_SECRET="cisco" EAPOL_NAS_IP_LIST="10.116.42.70,10.116.42.71,10.116.42.72,10.116.42.73,10.116.42.74,10.116.42.75,10.116.42.76,10.116.42.77,10.116.42.78,10.116.42.79" NAS_IP_MAX_INFLIGHT="30" NAS_LOCK_WAIT_MS="60000" CA_CERT="./ROOT_WIN-AD.cer" TLS_PFX_DIR="./certs-eap-tls" TLS_PFX_EXT=".pfx" PRIVATE_KEY_PASS="12345" TLS_MAC_FILE="./macs.txt" CSV_PATH="./users-10.csv" RPS_FILE="./tls_rps_sec.log" ERROR_LOG="./tls_errors.log" EAPOL_BIN="./eapol_test_2.11" EAPOL_TIMEOUT_SEC="60" EXEC_TIMEOUT_SEC="90" RPS_SECOND_STATS="true" LOG_ALL_FAILURES="true" K6_WEB_DASHBOARD="true" k6-exec run radius_load_tls.js | BC18: 10 | BD18: 10 | BE18: 10000 | BF18: 3 | BG18: 8 | BH18: 16 | BI18: 120
